{"timestamp": "2025-09-07T04:48:52.191284Z", "level": "ERROR", "logger": "django.request", "message": "Internal Server Error: /redis", "module": "log", "function": "log_response", "line": 248, "thread": 140474389608128, "process": 18, "status_code": 500, "environment": "development", "project": "fauxdan", "exception": "Traceback (most recent call last):\n  File \"/usr/local/lib/python3.10/site-packages/django/db/backends/utils.py\", line 105, in _execute\n    return self.cursor.execute(sql, params)\npsycopg2.errors.UniqueViolation: duplicate key value violates unique constraint \"analytics_session_session_id_key\"\nDETAIL:  Key (session_id)=(session_f4c6ac02-136a-4e2e-9f2e-2171eb2810cb_1757220531) already exists.\n\n\nThe above exception was the direct cause of the following exception:\n\nTraceback (most recent call last):\n  File \"/usr/local/lib/python3.10/site-packages/django/core/handlers/exception.py\", line 55, in inner\n    response = get_response(request)\n  File \"/usr/local/lib/python3.10/site-packages/django/utils/deprecation.py\", line 128, in __call__\n    response = self.process_request(request)\n  File \"/app/analytics/middleware.py\", line 84, in process_request\n    session = Session.objects.create(\n  File \"/usr/local/lib/python3.10/site-packages/django/db/models/manager.py\", line 87, in manager_method\n    return getattr(self.get_queryset(), name)(*args, **kwargs)\n  File \"/usr/local/lib/python3.10/site-packages/django/db/models/query.py\", line 679, in create\n    obj.save(force_insert=True, using=self.db)\n  File \"/usr/local/lib/python3.10/site-packages/django/db/models/base.py\", line 891, in save\n    self.save_base(\n  File \"/usr/local/lib/python3.10/site-packages/django/db/models/base.py\", line 997, in save_base\n    updated = self._save_table(\n  File \"/usr/local/lib/python3.10/site-packages/django/db/models/base.py\", line 1160, in _save_table\n    results = self._do_insert(\n  File \"/usr/local/lib/python3.10/site-packages/django/db/models/base.py\", line 1201, in _do_insert\n    return manager._insert(\n  File \"/usr/local/lib/python3.10/site-packages/django/db/models/manager.py\", line 87, in manager_method\n    return getattr(self.get_queryset(), name)(*args, **kwargs)\n  File \"/usr/local/lib/python3.10/site-packages/django/db/models/query.py\", line 1847, in _insert\n    return query.get_compiler(using=using).execute_sql(returning_fields)\n  File \"/usr/local/lib/python3.10/site-packages/django/db/models/sql/compiler.py\", line 1836, in execute_sql\n    cursor.execute(sql, params)\n  File \"/usr/local/lib/python3.10/site-packages/django/db/backends/utils.py\", line 122, in execute\n    return super().execute(sql, params)\n  File \"/usr/local/lib/python3.10/site-packages/django/db/backends/utils.py\", line 79, in execute\n    return self._execute_with_wrappers(\n  File \"/usr/local/lib/python3.10/site-packages/django/db/backends/utils.py\", line 92, in _execute_with_wrappers\n    return executor(sql, params, many, context)\n  File \"/usr/local/lib/python3.10/site-packages/django/db/backends/utils.py\", line 100, in _execute\n    with self.db.wrap_database_errors:\n  File \"/usr/local/lib/python3.10/site-packages/django/db/utils.py\", line 91, in __exit__\n    raise dj_exc_value.with_traceback(traceback) from exc_value\n  File \"/usr/local/lib/python3.10/site-packages/django/db/backends/utils.py\", line 105, in _execute\n    return self.cursor.execute(sql, params)\ndjango.db.utils.IntegrityError: duplicate key value violates unique constraint \"analytics_session_session_id_key\"\nDETAIL:  Key (session_id)=(session_f4c6ac02-136a-4e2e-9f2e-2171eb2810cb_1757220531) already exists.\n"}
{"timestamp": "2025-09-07T05:16:27.592167Z", "level": "ERROR", "logger": "django.request", "message": "Internal Server Error: /analytics/events/", "module": "log", "function": "log_response", "line": 248, "thread": 139720923281088, "process": 19, "status_code": 500, "environment": "development", "project": "fauxdan", "exception": "Traceback (most recent call last):\n  File \"/usr/local/lib/python3.10/site-packages/django/db/backends/utils.py\", line 105, in _execute\n    return self.cursor.execute(sql, params)\npsycopg2.errors.UniqueViolation: duplicate key value violates unique constraint \"analytics_session_session_id_key\"\nDETAIL:  Key (session_id)=(session_584441cb-db68-4405-b9ed-16156d75ce1c_1757222187) already exists.\n\n\nThe above exception was the direct cause of the following exception:\n\nTraceback (most recent call last):\n  File \"/usr/local/lib/python3.10/site-packages/django/core/handlers/exception.py\", line 55, in inner\n    response = get_response(request)\n  File \"/usr/local/lib/python3.10/site-packages/django/utils/deprecation.py\", line 128, in __call__\n    response = self.process_request(request)\n  File \"/app/analytics/middleware.py\", line 84, in process_request\n    session = Session.objects.create(\n  File \"/usr/local/lib/python3.10/site-packages/django/db/models/manager.py\", line 87, in manager_method\n    return getattr(self.get_queryset(), name)(*args, **kwargs)\n  File \"/usr/local/lib/python3.10/site-packages/django/db/models/query.py\", line 679, in create\n    obj.save(force_insert=True, using=self.db)\n  File \"/usr/local/lib/python3.10/site-packages/django/db/models/base.py\", line 891, in save\n    self.save_base(\n  File \"/usr/local/lib/python3.10/site-packages/django/db/models/base.py\", line 997, in save_base\n    updated = self._save_table(\n  File \"/usr/local/lib/python3.10/site-packages/django/db/models/base.py\", line 1160, in _save_table\n    results = self._do_insert(\n  File \"/usr/local/lib/python3.10/site-packages/django/db/models/base.py\", line 1201, in _do_insert\n    return manager._insert(\n  File \"/usr/local/lib/python3.10/site-packages/django/db/models/manager.py\", line 87, in manager_method\n    return getattr(self.get_queryset(), name)(*args, **kwargs)\n  File \"/usr/local/lib/python3.10/site-packages/django/db/models/query.py\", line 1847, in _insert\n    return query.get_compiler(using=using).execute_sql(returning_fields)\n  File \"/usr/local/lib/python3.10/site-packages/django/db/models/sql/compiler.py\", line 1836, in execute_sql\n    cursor.execute(sql, params)\n  File \"/usr/local/lib/python3.10/site-packages/django/db/backends/utils.py\", line 122, in execute\n    return super().execute(sql, params)\n  File \"/usr/local/lib/python3.10/site-packages/django/db/backends/utils.py\", line 79, in execute\n    return self._execute_with_wrappers(\n  File \"/usr/local/lib/python3.10/site-packages/django/db/backends/utils.py\", line 92, in _execute_with_wrappers\n    return executor(sql, params, many, context)\n  File \"/usr/local/lib/python3.10/site-packages/django/db/backends/utils.py\", line 100, in _execute\n    with self.db.wrap_database_errors:\n  File \"/usr/local/lib/python3.10/site-packages/django/db/utils.py\", line 91, in __exit__\n    raise dj_exc_value.with_traceback(traceback) from exc_value\n  File \"/usr/local/lib/python3.10/site-packages/django/db/backends/utils.py\", line 105, in _execute\n    return self.cursor.execute(sql, params)\ndjango.db.utils.IntegrityError: duplicate key value violates unique constraint \"analytics_session_session_id_key\"\nDETAIL:  Key (session_id)=(session_584441cb-db68-4405-b9ed-16156d75ce1c_1757222187) already exists.\n"}
{"timestamp": "2025-09-07T05:19:51.746180Z", "level": "ERROR", "logger": "django.request", "message": "Internal Server Error: /redis", "module": "log", "function": "log_response", "line": 248, "thread": 140474389608128, "process": 18, "status_code": 500, "environment": "development", "project": "fauxdan", "exception": "Traceback (most recent call last):\n  File \"/usr/local/lib/python3.10/site-packages/django/db/backends/utils.py\", line 105, in _execute\n    return self.cursor.execute(sql, params)\npsycopg2.errors.UniqueViolation: duplicate key value violates unique constraint \"analytics_session_session_id_key\"\nDETAIL:  Key (session_id)=(session_f4c6ac02-136a-4e2e-9f2e-2171eb2810cb_1757222391) already exists.\n\n\nThe above exception was the direct cause of the following exception:\n\nTraceback (most recent call last):\n  File \"/usr/local/lib/python3.10/site-packages/django/core/handlers/exception.py\", line 55, in inner\n    response = get_response(request)\n  File \"/usr/local/lib/python3.10/site-packages/django/utils/deprecation.py\", line 128, in __call__\n    response = self.process_request(request)\n  File \"/app/analytics/middleware.py\", line 84, in process_request\n    session = Session.objects.create(\n  File \"/usr/local/lib/python3.10/site-packages/django/db/models/manager.py\", line 87, in manager_method\n    return getattr(self.get_queryset(), name)(*args, **kwargs)\n  File \"/usr/local/lib/python3.10/site-packages/django/db/models/query.py\", line 679, in create\n    obj.save(force_insert=True, using=self.db)\n  File \"/usr/local/lib/python3.10/site-packages/django/db/models/base.py\", line 891, in save\n    self.save_base(\n  File \"/usr/local/lib/python3.10/site-packages/django/db/models/base.py\", line 997, in save_base\n    updated = self._save_table(\n  File \"/usr/local/lib/python3.10/site-packages/django/db/models/base.py\", line 1160, in _save_table\n    results = self._do_insert(\n  File \"/usr/local/lib/python3.10/site-packages/django/db/models/base.py\", line 1201, in _do_insert\n    return manager._insert(\n  File \"/usr/local/lib/python3.10/site-packages/django/db/models/manager.py\", line 87, in manager_method\n    return getattr(self.get_queryset(), name)(*args, **kwargs)\n  File \"/usr/local/lib/python3.10/site-packages/django/db/models/query.py\", line 1847, in _insert\n    return query.get_compiler(using=using).execute_sql(returning_fields)\n  File \"/usr/local/lib/python3.10/site-packages/django/db/models/sql/compiler.py\", line 1836, in execute_sql\n    cursor.execute(sql, params)\n  File \"/usr/local/lib/python3.10/site-packages/django/db/backends/utils.py\", line 122, in execute\n    return super().execute(sql, params)\n  File \"/usr/local/lib/python3.10/site-packages/django/db/backends/utils.py\", line 79, in execute\n    return self._execute_with_wrappers(\n  File \"/usr/local/lib/python3.10/site-packages/django/db/backends/utils.py\", line 92, in _execute_with_wrappers\n    return executor(sql, params, many, context)\n  File \"/usr/local/lib/python3.10/site-packages/django/db/backends/utils.py\", line 100, in _execute\n    with self.db.wrap_database_errors:\n  File \"/usr/local/lib/python3.10/site-packages/django/db/utils.py\", line 91, in __exit__\n    raise dj_exc_value.with_traceback(traceback) from exc_value\n  File \"/usr/local/lib/python3.10/site-packages/django/db/backends/utils.py\", line 105, in _execute\n    return self.cursor.execute(sql, params)\ndjango.db.utils.IntegrityError: duplicate key value violates unique constraint \"analytics_session_session_id_key\"\nDETAIL:  Key (session_id)=(session_f4c6ac02-136a-4e2e-9f2e-2171eb2810cb_1757222391) already exists.\n"}
{"timestamp": "2025-09-07T05:20:22.089112Z", "level": "ERROR", "logger": "django.request", "message": "Internal Server Error: /redis", "module": "log", "function": "log_response", "line": 248, "thread": 140474389608128, "process": 18, "status_code": 500, "environment": "development", "project": "fauxdan", "exception": "Traceback (most recent call last):\n  File \"/usr/local/lib/python3.10/site-packages/django/db/backends/utils.py\", line 105, in _execute\n    return self.cursor.execute(sql, params)\npsycopg2.errors.UniqueViolation: duplicate key value violates unique constraint \"analytics_session_session_id_key\"\nDETAIL:  Key (session_id)=(session_f4c6ac02-136a-4e2e-9f2e-2171eb2810cb_1757222421) already exists.\n\n\nThe above exception was the direct cause of the following exception:\n\nTraceback (most recent call last):\n  File \"/usr/local/lib/python3.10/site-packages/django/core/handlers/exception.py\", line 55, in inner\n    response = get_response(request)\n  File \"/usr/local/lib/python3.10/site-packages/django/utils/deprecation.py\", line 128, in __call__\n    response = self.process_request(request)\n  File \"/app/analytics/middleware.py\", line 84, in process_request\n    session = Session.objects.create(\n  File \"/usr/local/lib/python3.10/site-packages/django/db/models/manager.py\", line 87, in manager_method\n    return getattr(self.get_queryset(), name)(*args, **kwargs)\n  File \"/usr/local/lib/python3.10/site-packages/django/db/models/query.py\", line 679, in create\n    obj.save(force_insert=True, using=self.db)\n  File \"/usr/local/lib/python3.10/site-packages/django/db/models/base.py\", line 891, in save\n    self.save_base(\n  File \"/usr/local/lib/python3.10/site-packages/django/db/models/base.py\", line 997, in save_base\n    updated = self._save_table(\n  File \"/usr/local/lib/python3.10/site-packages/django/db/models/base.py\", line 1160, in _save_table\n    results = self._do_insert(\n  File \"/usr/local/lib/python3.10/site-packages/django/db/models/base.py\", line 1201, in _do_insert\n    return manager._insert(\n  File \"/usr/local/lib/python3.10/site-packages/django/db/models/manager.py\", line 87, in manager_method\n    return getattr(self.get_queryset(), name)(*args, **kwargs)\n  File \"/usr/local/lib/python3.10/site-packages/django/db/models/query.py\", line 1847, in _insert\n    return query.get_compiler(using=using).execute_sql(returning_fields)\n  File \"/usr/local/lib/python3.10/site-packages/django/db/models/sql/compiler.py\", line 1836, in execute_sql\n    cursor.execute(sql, params)\n  File \"/usr/local/lib/python3.10/site-packages/django/db/backends/utils.py\", line 122, in execute\n    return super().execute(sql, params)\n  File \"/usr/local/lib/python3.10/site-packages/django/db/backends/utils.py\", line 79, in execute\n    return self._execute_with_wrappers(\n  File \"/usr/local/lib/python3.10/site-packages/django/db/backends/utils.py\", line 92, in _execute_with_wrappers\n    return executor(sql, params, many, context)\n  File \"/usr/local/lib/python3.10/site-packages/django/db/backends/utils.py\", line 100, in _execute\n    with self.db.wrap_database_errors:\n  File \"/usr/local/lib/python3.10/site-packages/django/db/utils.py\", line 91, in __exit__\n    raise dj_exc_value.with_traceback(traceback) from exc_value\n  File \"/usr/local/lib/python3.10/site-packages/django/db/backends/utils.py\", line 105, in _execute\n    return self.cursor.execute(sql, params)\ndjango.db.utils.IntegrityError: duplicate key value violates unique constraint \"analytics_session_session_id_key\"\nDETAIL:  Key (session_id)=(session_f4c6ac02-136a-4e2e-9f2e-2171eb2810cb_1757222421) already exists.\n"}
{"timestamp": "2025-09-07T06:21:25.057734Z", "level": "ERROR", "logger": "django.request", "message": "Internal Server Error: /redis", "module": "log", "function": "log_response", "line": 248, "thread": 140474389608128, "process": 18, "status_code": 500, "environment": "development", "project": "fauxdan", "exception": "Traceback (most recent call last):\n  File \"/usr/local/lib/python3.10/site-packages/django/db/backends/utils.py\", line 105, in _execute\n    return self.cursor.execute(sql, params)\npsycopg2.errors.UniqueViolation: duplicate key value violates unique constraint \"analytics_session_session_id_key\"\nDETAIL:  Key (session_id)=(session_f4c6ac02-136a-4e2e-9f2e-2171eb2810cb_1757226084) already exists.\n\n\nThe above exception was the direct cause of the following exception:\n\nTraceback (most recent call last):\n  File \"/usr/local/lib/python3.10/site-packages/django/core/handlers/exception.py\", line 55, in inner\n    response = get_response(request)\n  File \"/usr/local/lib/python3.10/site-packages/django/utils/deprecation.py\", line 128, in __call__\n    response = self.process_request(request)\n  File \"/app/analytics/middleware.py\", line 84, in process_request\n    session = Session.objects.create(\n  File \"/usr/local/lib/python3.10/site-packages/django/db/models/manager.py\", line 87, in manager_method\n    return getattr(self.get_queryset(), name)(*args, **kwargs)\n  File \"/usr/local/lib/python3.10/site-packages/django/db/models/query.py\", line 679, in create\n    obj.save(force_insert=True, using=self.db)\n  File \"/usr/local/lib/python3.10/site-packages/django/db/models/base.py\", line 891, in save\n    self.save_base(\n  File \"/usr/local/lib/python3.10/site-packages/django/db/models/base.py\", line 997, in save_base\n    updated = self._save_table(\n  File \"/usr/local/lib/python3.10/site-packages/django/db/models/base.py\", line 1160, in _save_table\n    results = self._do_insert(\n  File \"/usr/local/lib/python3.10/site-packages/django/db/models/base.py\", line 1201, in _do_insert\n    return manager._insert(\n  File \"/usr/local/lib/python3.10/site-packages/django/db/models/manager.py\", line 87, in manager_method\n    return getattr(self.get_queryset(), name)(*args, **kwargs)\n  File \"/usr/local/lib/python3.10/site-packages/django/db/models/query.py\", line 1847, in _insert\n    return query.get_compiler(using=using).execute_sql(returning_fields)\n  File \"/usr/local/lib/python3.10/site-packages/django/db/models/sql/compiler.py\", line 1836, in execute_sql\n    cursor.execute(sql, params)\n  File \"/usr/local/lib/python3.10/site-packages/django/db/backends/utils.py\", line 122, in execute\n    return super().execute(sql, params)\n  File \"/usr/local/lib/python3.10/site-packages/django/db/backends/utils.py\", line 79, in execute\n    return self._execute_with_wrappers(\n  File \"/usr/local/lib/python3.10/site-packages/django/db/backends/utils.py\", line 92, in _execute_with_wrappers\n    return executor(sql, params, many, context)\n  File \"/usr/local/lib/python3.10/site-packages/django/db/backends/utils.py\", line 100, in _execute\n    with self.db.wrap_database_errors:\n  File \"/usr/local/lib/python3.10/site-packages/django/db/utils.py\", line 91, in __exit__\n    raise dj_exc_value.with_traceback(traceback) from exc_value\n  File \"/usr/local/lib/python3.10/site-packages/django/db/backends/utils.py\", line 105, in _execute\n    return self.cursor.execute(sql, params)\ndjango.db.utils.IntegrityError: duplicate key value violates unique constraint \"analytics_session_session_id_key\"\nDETAIL:  Key (session_id)=(session_f4c6ac02-136a-4e2e-9f2e-2171eb2810cb_1757226084) already exists.\n"}
{"timestamp": "2025-09-07T06:52:11.843327Z", "level": "ERROR", "logger": "django.request", "message": "Internal Server Error: /redis", "module": "log", "function": "log_response", "line": 248, "thread": 140474389608128, "process": 18, "status_code": 500, "environment": "development", "project": "fauxdan", "exception": "Traceback (most recent call last):\n  File \"/usr/local/lib/python3.10/site-packages/django/db/backends/utils.py\", line 105, in _execute\n    return self.cursor.execute(sql, params)\npsycopg2.errors.UniqueViolation: duplicate key value violates unique constraint \"analytics_session_session_id_key\"\nDETAIL:  Key (session_id)=(session_f4c6ac02-136a-4e2e-9f2e-2171eb2810cb_1757227931) already exists.\n\n\nThe above exception was the direct cause of the following exception:\n\nTraceback (most recent call last):\n  File \"/usr/local/lib/python3.10/site-packages/django/core/handlers/exception.py\", line 55, in inner\n    response = get_response(request)\n  File \"/usr/local/lib/python3.10/site-packages/django/utils/deprecation.py\", line 128, in __call__\n    response = self.process_request(request)\n  File \"/app/analytics/middleware.py\", line 84, in process_request\n    session = Session.objects.create(\n  File \"/usr/local/lib/python3.10/site-packages/django/db/models/manager.py\", line 87, in manager_method\n    return getattr(self.get_queryset(), name)(*args, **kwargs)\n  File \"/usr/local/lib/python3.10/site-packages/django/db/models/query.py\", line 679, in create\n    obj.save(force_insert=True, using=self.db)\n  File \"/usr/local/lib/python3.10/site-packages/django/db/models/base.py\", line 891, in save\n    self.save_base(\n  File \"/usr/local/lib/python3.10/site-packages/django/db/models/base.py\", line 997, in save_base\n    updated = self._save_table(\n  File \"/usr/local/lib/python3.10/site-packages/django/db/models/base.py\", line 1160, in _save_table\n    results = self._do_insert(\n  File \"/usr/local/lib/python3.10/site-packages/django/db/models/base.py\", line 1201, in _do_insert\n    return manager._insert(\n  File \"/usr/local/lib/python3.10/site-packages/django/db/models/manager.py\", line 87, in manager_method\n    return getattr(self.get_queryset(), name)(*args, **kwargs)\n  File \"/usr/local/lib/python3.10/site-packages/django/db/models/query.py\", line 1847, in _insert\n    return query.get_compiler(using=using).execute_sql(returning_fields)\n  File \"/usr/local/lib/python3.10/site-packages/django/db/models/sql/compiler.py\", line 1836, in execute_sql\n    cursor.execute(sql, params)\n  File \"/usr/local/lib/python3.10/site-packages/django/db/backends/utils.py\", line 122, in execute\n    return super().execute(sql, params)\n  File \"/usr/local/lib/python3.10/site-packages/django/db/backends/utils.py\", line 79, in execute\n    return self._execute_with_wrappers(\n  File \"/usr/local/lib/python3.10/site-packages/django/db/backends/utils.py\", line 92, in _execute_with_wrappers\n    return executor(sql, params, many, context)\n  File \"/usr/local/lib/python3.10/site-packages/django/db/backends/utils.py\", line 100, in _execute\n    with self.db.wrap_database_errors:\n  File \"/usr/local/lib/python3.10/site-packages/django/db/utils.py\", line 91, in __exit__\n    raise dj_exc_value.with_traceback(traceback) from exc_value\n  File \"/usr/local/lib/python3.10/site-packages/django/db/backends/utils.py\", line 105, in _execute\n    return self.cursor.execute(sql, params)\ndjango.db.utils.IntegrityError: duplicate key value violates unique constraint \"analytics_session_session_id_key\"\nDETAIL:  Key (session_id)=(session_f4c6ac02-136a-4e2e-9f2e-2171eb2810cb_1757227931) already exists.\n"}
{"timestamp": "2025-09-07T07:53:15.015753Z", "level": "ERROR", "logger": "django.request", "message": "Internal Server Error: /redis", "module": "log", "function": "log_response", "line": 248, "thread": 140474389608128, "process": 18, "status_code": 500, "environment": "development", "project": "fauxdan", "exception": "Traceback (most recent call last):\n  File \"/usr/local/lib/python3.10/site-packages/django/db/backends/utils.py\", line 105, in _execute\n    return self.cursor.execute(sql, params)\npsycopg2.errors.UniqueViolation: duplicate key value violates unique constraint \"analytics_session_session_id_key\"\nDETAIL:  Key (session_id)=(session_f4c6ac02-136a-4e2e-9f2e-2171eb2810cb_1757231594) already exists.\n\n\nThe above exception was the direct cause of the following exception:\n\nTraceback (most recent call last):\n  File \"/usr/local/lib/python3.10/site-packages/django/core/handlers/exception.py\", line 55, in inner\n    response = get_response(request)\n  File \"/usr/local/lib/python3.10/site-packages/django/utils/deprecation.py\", line 128, in __call__\n    response = self.process_request(request)\n  File \"/app/analytics/middleware.py\", line 84, in process_request\n    session = Session.objects.create(\n  File \"/usr/local/lib/python3.10/site-packages/django/db/models/manager.py\", line 87, in manager_method\n    return getattr(self.get_queryset(), name)(*args, **kwargs)\n  File \"/usr/local/lib/python3.10/site-packages/django/db/models/query.py\", line 679, in create\n    obj.save(force_insert=True, using=self.db)\n  File \"/usr/local/lib/python3.10/site-packages/django/db/models/base.py\", line 891, in save\n    self.save_base(\n  File \"/usr/local/lib/python3.10/site-packages/django/db/models/base.py\", line 997, in save_base\n    updated = self._save_table(\n  File \"/usr/local/lib/python3.10/site-packages/django/db/models/base.py\", line 1160, in _save_table\n    results = self._do_insert(\n  File \"/usr/local/lib/python3.10/site-packages/django/db/models/base.py\", line 1201, in _do_insert\n    return manager._insert(\n  File \"/usr/local/lib/python3.10/site-packages/django/db/models/manager.py\", line 87, in manager_method\n    return getattr(self.get_queryset(), name)(*args, **kwargs)\n  File \"/usr/local/lib/python3.10/site-packages/django/db/models/query.py\", line 1847, in _insert\n    return query.get_compiler(using=using).execute_sql(returning_fields)\n  File \"/usr/local/lib/python3.10/site-packages/django/db/models/sql/compiler.py\", line 1836, in execute_sql\n    cursor.execute(sql, params)\n  File \"/usr/local/lib/python3.10/site-packages/django/db/backends/utils.py\", line 122, in execute\n    return super().execute(sql, params)\n  File \"/usr/local/lib/python3.10/site-packages/django/db/backends/utils.py\", line 79, in execute\n    return self._execute_with_wrappers(\n  File \"/usr/local/lib/python3.10/site-packages/django/db/backends/utils.py\", line 92, in _execute_with_wrappers\n    return executor(sql, params, many, context)\n  File \"/usr/local/lib/python3.10/site-packages/django/db/backends/utils.py\", line 100, in _execute\n    with self.db.wrap_database_errors:\n  File \"/usr/local/lib/python3.10/site-packages/django/db/utils.py\", line 91, in __exit__\n    raise dj_exc_value.with_traceback(traceback) from exc_value\n  File \"/usr/local/lib/python3.10/site-packages/django/db/backends/utils.py\", line 105, in _execute\n    return self.cursor.execute(sql, params)\ndjango.db.utils.IntegrityError: duplicate key value violates unique constraint \"analytics_session_session_id_key\"\nDETAIL:  Key (session_id)=(session_f4c6ac02-136a-4e2e-9f2e-2171eb2810cb_1757231594) already exists.\n"}
{"timestamp": "2025-09-07T08:24:02.887702Z", "level": "ERROR", "logger": "django.request", "message": "Internal Server Error: /redis", "module": "log", "function": "log_response", "line": 248, "thread": 140474389608128, "process": 18, "status_code": 500, "environment": "development", "project": "fauxdan", "exception": "Traceback (most recent call last):\n  File \"/usr/local/lib/python3.10/site-packages/django/db/backends/utils.py\", line 105, in _execute\n    return self.cursor.execute(sql, params)\npsycopg2.errors.UniqueViolation: duplicate key value violates unique constraint \"analytics_session_session_id_key\"\nDETAIL:  Key (session_id)=(session_f4c6ac02-136a-4e2e-9f2e-2171eb2810cb_1757233442) already exists.\n\n\nThe above exception was the direct cause of the following exception:\n\nTraceback (most recent call last):\n  File \"/usr/local/lib/python3.10/site-packages/django/core/handlers/exception.py\", line 55, in inner\n    response = get_response(request)\n  File \"/usr/local/lib/python3.10/site-packages/django/utils/deprecation.py\", line 128, in __call__\n    response = self.process_request(request)\n  File \"/app/analytics/middleware.py\", line 84, in process_request\n    session = Session.objects.create(\n  File \"/usr/local/lib/python3.10/site-packages/django/db/models/manager.py\", line 87, in manager_method\n    return getattr(self.get_queryset(), name)(*args, **kwargs)\n  File \"/usr/local/lib/python3.10/site-packages/django/db/models/query.py\", line 679, in create\n    obj.save(force_insert=True, using=self.db)\n  File \"/usr/local/lib/python3.10/site-packages/django/db/models/base.py\", line 891, in save\n    self.save_base(\n  File \"/usr/local/lib/python3.10/site-packages/django/db/models/base.py\", line 997, in save_base\n    updated = self._save_table(\n  File \"/usr/local/lib/python3.10/site-packages/django/db/models/base.py\", line 1160, in _save_table\n    results = self._do_insert(\n  File \"/usr/local/lib/python3.10/site-packages/django/db/models/base.py\", line 1201, in _do_insert\n    return manager._insert(\n  File \"/usr/local/lib/python3.10/site-packages/django/db/models/manager.py\", line 87, in manager_method\n    return getattr(self.get_queryset(), name)(*args, **kwargs)\n  File \"/usr/local/lib/python3.10/site-packages/django/db/models/query.py\", line 1847, in _insert\n    return query.get_compiler(using=using).execute_sql(returning_fields)\n  File \"/usr/local/lib/python3.10/site-packages/django/db/models/sql/compiler.py\", line 1836, in execute_sql\n    cursor.execute(sql, params)\n  File \"/usr/local/lib/python3.10/site-packages/django/db/backends/utils.py\", line 122, in execute\n    return super().execute(sql, params)\n  File \"/usr/local/lib/python3.10/site-packages/django/db/backends/utils.py\", line 79, in execute\n    return self._execute_with_wrappers(\n  File \"/usr/local/lib/python3.10/site-packages/django/db/backends/utils.py\", line 92, in _execute_with_wrappers\n    return executor(sql, params, many, context)\n  File \"/usr/local/lib/python3.10/site-packages/django/db/backends/utils.py\", line 100, in _execute\n    with self.db.wrap_database_errors:\n  File \"/usr/local/lib/python3.10/site-packages/django/db/utils.py\", line 91, in __exit__\n    raise dj_exc_value.with_traceback(traceback) from exc_value\n  File \"/usr/local/lib/python3.10/site-packages/django/db/backends/utils.py\", line 105, in _execute\n    return self.cursor.execute(sql, params)\ndjango.db.utils.IntegrityError: duplicate key value violates unique constraint \"analytics_session_session_id_key\"\nDETAIL:  Key (session_id)=(session_f4c6ac02-136a-4e2e-9f2e-2171eb2810cb_1757233442) already exists.\n"}
{"timestamp": "2025-09-07T10:26:29.680064Z", "level": "ERROR", "logger": "django.request", "message": "Internal Server Error: /redis", "module": "log", "function": "log_response", "line": 248, "thread": 140474389608128, "process": 18, "status_code": 500, "environment": "development", "project": "fauxdan", "exception": "Traceback (most recent call last):\n  File \"/usr/local/lib/python3.10/site-packages/django/db/backends/utils.py\", line 105, in _execute\n    return self.cursor.execute(sql, params)\npsycopg2.errors.UniqueViolation: duplicate key value violates unique constraint \"analytics_session_session_id_key\"\nDETAIL:  Key (session_id)=(session_f4c6ac02-136a-4e2e-9f2e-2171eb2810cb_1757240789) already exists.\n\n\nThe above exception was the direct cause of the following exception:\n\nTraceback (most recent call last):\n  File \"/usr/local/lib/python3.10/site-packages/django/core/handlers/exception.py\", line 55, in inner\n    response = get_response(request)\n  File \"/usr/local/lib/python3.10/site-packages/django/utils/deprecation.py\", line 128, in __call__\n    response = self.process_request(request)\n  File \"/app/analytics/middleware.py\", line 84, in process_request\n    session = Session.objects.create(\n  File \"/usr/local/lib/python3.10/site-packages/django/db/models/manager.py\", line 87, in manager_method\n    return getattr(self.get_queryset(), name)(*args, **kwargs)\n  File \"/usr/local/lib/python3.10/site-packages/django/db/models/query.py\", line 679, in create\n    obj.save(force_insert=True, using=self.db)\n  File \"/usr/local/lib/python3.10/site-packages/django/db/models/base.py\", line 891, in save\n    self.save_base(\n  File \"/usr/local/lib/python3.10/site-packages/django/db/models/base.py\", line 997, in save_base\n    updated = self._save_table(\n  File \"/usr/local/lib/python3.10/site-packages/django/db/models/base.py\", line 1160, in _save_table\n    results = self._do_insert(\n  File \"/usr/local/lib/python3.10/site-packages/django/db/models/base.py\", line 1201, in _do_insert\n    return manager._insert(\n  File \"/usr/local/lib/python3.10/site-packages/django/db/models/manager.py\", line 87, in manager_method\n    return getattr(self.get_queryset(), name)(*args, **kwargs)\n  File \"/usr/local/lib/python3.10/site-packages/django/db/models/query.py\", line 1847, in _insert\n    return query.get_compiler(using=using).execute_sql(returning_fields)\n  File \"/usr/local/lib/python3.10/site-packages/django/db/models/sql/compiler.py\", line 1836, in execute_sql\n    cursor.execute(sql, params)\n  File \"/usr/local/lib/python3.10/site-packages/django/db/backends/utils.py\", line 122, in execute\n    return super().execute(sql, params)\n  File \"/usr/local/lib/python3.10/site-packages/django/db/backends/utils.py\", line 79, in execute\n    return self._execute_with_wrappers(\n  File \"/usr/local/lib/python3.10/site-packages/django/db/backends/utils.py\", line 92, in _execute_with_wrappers\n    return executor(sql, params, many, context)\n  File \"/usr/local/lib/python3.10/site-packages/django/db/backends/utils.py\", line 100, in _execute\n    with self.db.wrap_database_errors:\n  File \"/usr/local/lib/python3.10/site-packages/django/db/utils.py\", line 91, in __exit__\n    raise dj_exc_value.with_traceback(traceback) from exc_value\n  File \"/usr/local/lib/python3.10/site-packages/django/db/backends/utils.py\", line 105, in _execute\n    return self.cursor.execute(sql, params)\ndjango.db.utils.IntegrityError: duplicate key value violates unique constraint \"analytics_session_session_id_key\"\nDETAIL:  Key (session_id)=(session_f4c6ac02-136a-4e2e-9f2e-2171eb2810cb_1757240789) already exists.\n"}
{"timestamp": "2025-09-07T10:26:59.929617Z", "level": "ERROR", "logger": "django.request", "message": "Internal Server Error: /redis", "module": "log", "function": "log_response", "line": 248, "thread": 140474389608128, "process": 18, "status_code": 500, "environment": "development", "project": "fauxdan", "exception": "Traceback (most recent call last):\n  File \"/usr/local/lib/python3.10/site-packages/django/db/backends/utils.py\", line 105, in _execute\n    return self.cursor.execute(sql, params)\npsycopg2.errors.UniqueViolation: duplicate key value violates unique constraint \"analytics_session_session_id_key\"\nDETAIL:  Key (session_id)=(session_f4c6ac02-136a-4e2e-9f2e-2171eb2810cb_1757240819) already exists.\n\n\nThe above exception was the direct cause of the following exception:\n\nTraceback (most recent call last):\n  File \"/usr/local/lib/python3.10/site-packages/django/core/handlers/exception.py\", line 55, in inner\n    response = get_response(request)\n  File \"/usr/local/lib/python3.10/site-packages/django/utils/deprecation.py\", line 128, in __call__\n    response = self.process_request(request)\n  File \"/app/analytics/middleware.py\", line 84, in process_request\n    session = Session.objects.create(\n  File \"/usr/local/lib/python3.10/site-packages/django/db/models/manager.py\", line 87, in manager_method\n    return getattr(self.get_queryset(), name)(*args, **kwargs)\n  File \"/usr/local/lib/python3.10/site-packages/django/db/models/query.py\", line 679, in create\n    obj.save(force_insert=True, using=self.db)\n  File \"/usr/local/lib/python3.10/site-packages/django/db/models/base.py\", line 891, in save\n    self.save_base(\n  File \"/usr/local/lib/python3.10/site-packages/django/db/models/base.py\", line 997, in save_base\n    updated = self._save_table(\n  File \"/usr/local/lib/python3.10/site-packages/django/db/models/base.py\", line 1160, in _save_table\n    results = self._do_insert(\n  File \"/usr/local/lib/python3.10/site-packages/django/db/models/base.py\", line 1201, in _do_insert\n    return manager._insert(\n  File \"/usr/local/lib/python3.10/site-packages/django/db/models/manager.py\", line 87, in manager_method\n    return getattr(self.get_queryset(), name)(*args, **kwargs)\n  File \"/usr/local/lib/python3.10/site-packages/django/db/models/query.py\", line 1847, in _insert\n    return query.get_compiler(using=using).execute_sql(returning_fields)\n  File \"/usr/local/lib/python3.10/site-packages/django/db/models/sql/compiler.py\", line 1836, in execute_sql\n    cursor.execute(sql, params)\n  File \"/usr/local/lib/python3.10/site-packages/django/db/backends/utils.py\", line 122, in execute\n    return super().execute(sql, params)\n  File \"/usr/local/lib/python3.10/site-packages/django/db/backends/utils.py\", line 79, in execute\n    return self._execute_with_wrappers(\n  File \"/usr/local/lib/python3.10/site-packages/django/db/backends/utils.py\", line 92, in _execute_with_wrappers\n    return executor(sql, params, many, context)\n  File \"/usr/local/lib/python3.10/site-packages/django/db/backends/utils.py\", line 100, in _execute\n    with self.db.wrap_database_errors:\n  File \"/usr/local/lib/python3.10/site-packages/django/db/utils.py\", line 91, in __exit__\n    raise dj_exc_value.with_traceback(traceback) from exc_value\n  File \"/usr/local/lib/python3.10/site-packages/django/db/backends/utils.py\", line 105, in _execute\n    return self.cursor.execute(sql, params)\ndjango.db.utils.IntegrityError: duplicate key value violates unique constraint \"analytics_session_session_id_key\"\nDETAIL:  Key (session_id)=(session_f4c6ac02-136a-4e2e-9f2e-2171eb2810cb_1757240819) already exists.\n"}
{"timestamp": "2025-09-07T11:28:00.795649Z", "level": "ERROR", "logger": "django.request", "message": "Internal Server Error: /redis", "module": "log", "function": "log_response", "line": 248, "thread": 140474389608128, "process": 18, "status_code": 500, "environment": "development", "project": "fauxdan", "exception": "Traceback (most recent call last):\n  File \"/usr/local/lib/python3.10/site-packages/django/db/backends/utils.py\", line 105, in _execute\n    return self.cursor.execute(sql, params)\npsycopg2.errors.UniqueViolation: duplicate key value violates unique constraint \"analytics_session_session_id_key\"\nDETAIL:  Key (session_id)=(session_f4c6ac02-136a-4e2e-9f2e-2171eb2810cb_1757244480) already exists.\n\n\nThe above exception was the direct cause of the following exception:\n\nTraceback (most recent call last):\n  File \"/usr/local/lib/python3.10/site-packages/django/core/handlers/exception.py\", line 55, in inner\n    response = get_response(request)\n  File \"/usr/local/lib/python3.10/site-packages/django/utils/deprecation.py\", line 128, in __call__\n    response = self.process_request(request)\n  File \"/app/analytics/middleware.py\", line 84, in process_request\n    session = Session.objects.create(\n  File \"/usr/local/lib/python3.10/site-packages/django/db/models/manager.py\", line 87, in manager_method\n    return getattr(self.get_queryset(), name)(*args, **kwargs)\n  File \"/usr/local/lib/python3.10/site-packages/django/db/models/query.py\", line 679, in create\n    obj.save(force_insert=True, using=self.db)\n  File \"/usr/local/lib/python3.10/site-packages/django/db/models/base.py\", line 891, in save\n    self.save_base(\n  File \"/usr/local/lib/python3.10/site-packages/django/db/models/base.py\", line 997, in save_base\n    updated = self._save_table(\n  File \"/usr/local/lib/python3.10/site-packages/django/db/models/base.py\", line 1160, in _save_table\n    results = self._do_insert(\n  File \"/usr/local/lib/python3.10/site-packages/django/db/models/base.py\", line 1201, in _do_insert\n    return manager._insert(\n  File \"/usr/local/lib/python3.10/site-packages/django/db/models/manager.py\", line 87, in manager_method\n    return getattr(self.get_queryset(), name)(*args, **kwargs)\n  File \"/usr/local/lib/python3.10/site-packages/django/db/models/query.py\", line 1847, in _insert\n    return query.get_compiler(using=using).execute_sql(returning_fields)\n  File \"/usr/local/lib/python3.10/site-packages/django/db/models/sql/compiler.py\", line 1836, in execute_sql\n    cursor.execute(sql, params)\n  File \"/usr/local/lib/python3.10/site-packages/django/db/backends/utils.py\", line 122, in execute\n    return super().execute(sql, params)\n  File \"/usr/local/lib/python3.10/site-packages/django/db/backends/utils.py\", line 79, in execute\n    return self._execute_with_wrappers(\n  File \"/usr/local/lib/python3.10/site-packages/django/db/backends/utils.py\", line 92, in _execute_with_wrappers\n    return executor(sql, params, many, context)\n  File \"/usr/local/lib/python3.10/site-packages/django/db/backends/utils.py\", line 100, in _execute\n    with self.db.wrap_database_errors:\n  File \"/usr/local/lib/python3.10/site-packages/django/db/utils.py\", line 91, in __exit__\n    raise dj_exc_value.with_traceback(traceback) from exc_value\n  File \"/usr/local/lib/python3.10/site-packages/django/db/backends/utils.py\", line 105, in _execute\n    return self.cursor.execute(sql, params)\ndjango.db.utils.IntegrityError: duplicate key value violates unique constraint \"analytics_session_session_id_key\"\nDETAIL:  Key (session_id)=(session_f4c6ac02-136a-4e2e-9f2e-2171eb2810cb_1757244480) already exists.\n"}
{"timestamp": "2025-09-07T11:59:01.829509Z", "level": "ERROR", "logger": "django.request", "message": "Internal Server Error: /redis", "module": "log", "function": "log_response", "line": 248, "thread": 140474389608128, "process": 18, "status_code": 500, "environment": "development", "project": "fauxdan", "exception": "Traceback (most recent call last):\n  File \"/usr/local/lib/python3.10/site-packages/django/db/backends/utils.py\", line 105, in _execute\n    return self.cursor.execute(sql, params)\npsycopg2.errors.UniqueViolation: duplicate key value violates unique constraint \"analytics_session_session_id_key\"\nDETAIL:  Key (session_id)=(session_f4c6ac02-136a-4e2e-9f2e-2171eb2810cb_1757246341) already exists.\n\n\nThe above exception was the direct cause of the following exception:\n\nTraceback (most recent call last):\n  File \"/usr/local/lib/python3.10/site-packages/django/core/handlers/exception.py\", line 55, in inner\n    response = get_response(request)\n  File \"/usr/local/lib/python3.10/site-packages/django/utils/deprecation.py\", line 128, in __call__\n    response = self.process_request(request)\n  File \"/app/analytics/middleware.py\", line 84, in process_request\n    session = Session.objects.create(\n  File \"/usr/local/lib/python3.10/site-packages/django/db/models/manager.py\", line 87, in manager_method\n    return getattr(self.get_queryset(), name)(*args, **kwargs)\n  File \"/usr/local/lib/python3.10/site-packages/django/db/models/query.py\", line 679, in create\n    obj.save(force_insert=True, using=self.db)\n  File \"/usr/local/lib/python3.10/site-packages/django/db/models/base.py\", line 891, in save\n    self.save_base(\n  File \"/usr/local/lib/python3.10/site-packages/django/db/models/base.py\", line 997, in save_base\n    updated = self._save_table(\n  File \"/usr/local/lib/python3.10/site-packages/django/db/models/base.py\", line 1160, in _save_table\n    results = self._do_insert(\n  File \"/usr/local/lib/python3.10/site-packages/django/db/models/base.py\", line 1201, in _do_insert\n    return manager._insert(\n  File \"/usr/local/lib/python3.10/site-packages/django/db/models/manager.py\", line 87, in manager_method\n    return getattr(self.get_queryset(), name)(*args, **kwargs)\n  File \"/usr/local/lib/python3.10/site-packages/django/db/models/query.py\", line 1847, in _insert\n    return query.get_compiler(using=using).execute_sql(returning_fields)\n  File \"/usr/local/lib/python3.10/site-packages/django/db/models/sql/compiler.py\", line 1836, in execute_sql\n    cursor.execute(sql, params)\n  File \"/usr/local/lib/python3.10/site-packages/django/db/backends/utils.py\", line 122, in execute\n    return super().execute(sql, params)\n  File \"/usr/local/lib/python3.10/site-packages/django/db/backends/utils.py\", line 79, in execute\n    return self._execute_with_wrappers(\n  File \"/usr/local/lib/python3.10/site-packages/django/db/backends/utils.py\", line 92, in _execute_with_wrappers\n    return executor(sql, params, many, context)\n  File \"/usr/local/lib/python3.10/site-packages/django/db/backends/utils.py\", line 100, in _execute\n    with self.db.wrap_database_errors:\n  File \"/usr/local/lib/python3.10/site-packages/django/db/utils.py\", line 91, in __exit__\n    raise dj_exc_value.with_traceback(traceback) from exc_value\n  File \"/usr/local/lib/python3.10/site-packages/django/db/backends/utils.py\", line 105, in _execute\n    return self.cursor.execute(sql, params)\ndjango.db.utils.IntegrityError: duplicate key value violates unique constraint \"analytics_session_session_id_key\"\nDETAIL:  Key (session_id)=(session_f4c6ac02-136a-4e2e-9f2e-2171eb2810cb_1757246341) already exists.\n"}
{"timestamp": "2025-09-07T14:07:24.109040Z", "level": "ERROR", "logger": "django.request", "message": "Internal Server Error: /analytics/events/", "module": "log", "function": "log_response", "line": 248, "thread": 139720914888384, "process": 19, "status_code": 500, "environment": "development", "project": "fauxdan", "exception": "Traceback (most recent call last):\n  File \"/usr/local/lib/python3.10/site-packages/django/db/backends/utils.py\", line 105, in _execute\n    return self.cursor.execute(sql, params)\npsycopg2.errors.UniqueViolation: duplicate key value violates unique constraint \"analytics_session_session_id_key\"\nDETAIL:  Key (session_id)=(session_584441cb-db68-4405-b9ed-16156d75ce1c_1757254043) already exists.\n\n\nThe above exception was the direct cause of the following exception:\n\nTraceback (most recent call last):\n  File \"/usr/local/lib/python3.10/site-packages/django/core/handlers/exception.py\", line 55, in inner\n    response = get_response(request)\n  File \"/usr/local/lib/python3.10/site-packages/django/utils/deprecation.py\", line 128, in __call__\n    response = self.process_request(request)\n  File \"/app/analytics/middleware.py\", line 84, in process_request\n    session = Session.objects.create(\n  File \"/usr/local/lib/python3.10/site-packages/django/db/models/manager.py\", line 87, in manager_method\n    return getattr(self.get_queryset(), name)(*args, **kwargs)\n  File \"/usr/local/lib/python3.10/site-packages/django/db/models/query.py\", line 679, in create\n    obj.save(force_insert=True, using=self.db)\n  File \"/usr/local/lib/python3.10/site-packages/django/db/models/base.py\", line 891, in save\n    self.save_base(\n  File \"/usr/local/lib/python3.10/site-packages/django/db/models/base.py\", line 997, in save_base\n    updated = self._save_table(\n  File \"/usr/local/lib/python3.10/site-packages/django/db/models/base.py\", line 1160, in _save_table\n    results = self._do_insert(\n  File \"/usr/local/lib/python3.10/site-packages/django/db/models/base.py\", line 1201, in _do_insert\n    return manager._insert(\n  File \"/usr/local/lib/python3.10/site-packages/django/db/models/manager.py\", line 87, in manager_method\n    return getattr(self.get_queryset(), name)(*args, **kwargs)\n  File \"/usr/local/lib/python3.10/site-packages/django/db/models/query.py\", line 1847, in _insert\n    return query.get_compiler(using=using).execute_sql(returning_fields)\n  File \"/usr/local/lib/python3.10/site-packages/django/db/models/sql/compiler.py\", line 1836, in execute_sql\n    cursor.execute(sql, params)\n  File \"/usr/local/lib/python3.10/site-packages/django/db/backends/utils.py\", line 122, in execute\n    return super().execute(sql, params)\n  File \"/usr/local/lib/python3.10/site-packages/django/db/backends/utils.py\", line 79, in execute\n    return self._execute_with_wrappers(\n  File \"/usr/local/lib/python3.10/site-packages/django/db/backends/utils.py\", line 92, in _execute_with_wrappers\n    return executor(sql, params, many, context)\n  File \"/usr/local/lib/python3.10/site-packages/django/db/backends/utils.py\", line 100, in _execute\n    with self.db.wrap_database_errors:\n  File \"/usr/local/lib/python3.10/site-packages/django/db/utils.py\", line 91, in __exit__\n    raise dj_exc_value.with_traceback(traceback) from exc_value\n  File \"/usr/local/lib/python3.10/site-packages/django/db/backends/utils.py\", line 105, in _execute\n    return self.cursor.execute(sql, params)\ndjango.db.utils.IntegrityError: duplicate key value violates unique constraint \"analytics_session_session_id_key\"\nDETAIL:  Key (session_id)=(session_584441cb-db68-4405-b9ed-16156d75ce1c_1757254043) already exists.\n"}
{"timestamp": "2025-09-07T14:31:45.703350Z", "level": "ERROR", "logger": "django.request", "message": "Internal Server Error: /redis", "module": "log", "function": "log_response", "line": 248, "thread": 140474389608128, "process": 18, "status_code": 500, "environment": "development", "project": "fauxdan", "exception": "Traceback (most recent call last):\n  File \"/usr/local/lib/python3.10/site-packages/django/db/backends/utils.py\", line 105, in _execute\n    return self.cursor.execute(sql, params)\npsycopg2.errors.UniqueViolation: duplicate key value violates unique constraint \"analytics_session_session_id_key\"\nDETAIL:  Key (session_id)=(session_f4c6ac02-136a-4e2e-9f2e-2171eb2810cb_1757255505) already exists.\n\n\nThe above exception was the direct cause of the following exception:\n\nTraceback (most recent call last):\n  File \"/usr/local/lib/python3.10/site-packages/django/core/handlers/exception.py\", line 55, in inner\n    response = get_response(request)\n  File \"/usr/local/lib/python3.10/site-packages/django/utils/deprecation.py\", line 128, in __call__\n    response = self.process_request(request)\n  File \"/app/analytics/middleware.py\", line 84, in process_request\n    session = Session.objects.create(\n  File \"/usr/local/lib/python3.10/site-packages/django/db/models/manager.py\", line 87, in manager_method\n    return getattr(self.get_queryset(), name)(*args, **kwargs)\n  File \"/usr/local/lib/python3.10/site-packages/django/db/models/query.py\", line 679, in create\n    obj.save(force_insert=True, using=self.db)\n  File \"/usr/local/lib/python3.10/site-packages/django/db/models/base.py\", line 891, in save\n    self.save_base(\n  File \"/usr/local/lib/python3.10/site-packages/django/db/models/base.py\", line 997, in save_base\n    updated = self._save_table(\n  File \"/usr/local/lib/python3.10/site-packages/django/db/models/base.py\", line 1160, in _save_table\n    results = self._do_insert(\n  File \"/usr/local/lib/python3.10/site-packages/django/db/models/base.py\", line 1201, in _do_insert\n    return manager._insert(\n  File \"/usr/local/lib/python3.10/site-packages/django/db/models/manager.py\", line 87, in manager_method\n    return getattr(self.get_queryset(), name)(*args, **kwargs)\n  File \"/usr/local/lib/python3.10/site-packages/django/db/models/query.py\", line 1847, in _insert\n    return query.get_compiler(using=using).execute_sql(returning_fields)\n  File \"/usr/local/lib/python3.10/site-packages/django/db/models/sql/compiler.py\", line 1836, in execute_sql\n    cursor.execute(sql, params)\n  File \"/usr/local/lib/python3.10/site-packages/django/db/backends/utils.py\", line 122, in execute\n    return super().execute(sql, params)\n  File \"/usr/local/lib/python3.10/site-packages/django/db/backends/utils.py\", line 79, in execute\n    return self._execute_with_wrappers(\n  File \"/usr/local/lib/python3.10/site-packages/django/db/backends/utils.py\", line 92, in _execute_with_wrappers\n    return executor(sql, params, many, context)\n  File \"/usr/local/lib/python3.10/site-packages/django/db/backends/utils.py\", line 100, in _execute\n    with self.db.wrap_database_errors:\n  File \"/usr/local/lib/python3.10/site-packages/django/db/utils.py\", line 91, in __exit__\n    raise dj_exc_value.with_traceback(traceback) from exc_value\n  File \"/usr/local/lib/python3.10/site-packages/django/db/backends/utils.py\", line 105, in _execute\n    return self.cursor.execute(sql, params)\ndjango.db.utils.IntegrityError: duplicate key value violates unique constraint \"analytics_session_session_id_key\"\nDETAIL:  Key (session_id)=(session_f4c6ac02-136a-4e2e-9f2e-2171eb2810cb_1757255505) already exists.\n"}
{"timestamp": "2025-09-07T14:32:16.017464Z", "level": "ERROR", "logger": "django.request", "message": "Internal Server Error: /redis", "module": "log", "function": "log_response", "line": 248, "thread": 140474389608128, "process": 18, "status_code": 500, "environment": "development", "project": "fauxdan", "exception": "Traceback (most recent call last):\n  File \"/usr/local/lib/python3.10/site-packages/django/db/backends/utils.py\", line 105, in _execute\n    return self.cursor.execute(sql, params)\npsycopg2.errors.UniqueViolation: duplicate key value violates unique constraint \"analytics_session_session_id_key\"\nDETAIL:  Key (session_id)=(session_f4c6ac02-136a-4e2e-9f2e-2171eb2810cb_1757255535) already exists.\n\n\nThe above exception was the direct cause of the following exception:\n\nTraceback (most recent call last):\n  File \"/usr/local/lib/python3.10/site-packages/django/core/handlers/exception.py\", line 55, in inner\n    response = get_response(request)\n  File \"/usr/local/lib/python3.10/site-packages/django/utils/deprecation.py\", line 128, in __call__\n    response = self.process_request(request)\n  File \"/app/analytics/middleware.py\", line 84, in process_request\n    session = Session.objects.create(\n  File \"/usr/local/lib/python3.10/site-packages/django/db/models/manager.py\", line 87, in manager_method\n    return getattr(self.get_queryset(), name)(*args, **kwargs)\n  File \"/usr/local/lib/python3.10/site-packages/django/db/models/query.py\", line 679, in create\n    obj.save(force_insert=True, using=self.db)\n  File \"/usr/local/lib/python3.10/site-packages/django/db/models/base.py\", line 891, in save\n    self.save_base(\n  File \"/usr/local/lib/python3.10/site-packages/django/db/models/base.py\", line 997, in save_base\n    updated = self._save_table(\n  File \"/usr/local/lib/python3.10/site-packages/django/db/models/base.py\", line 1160, in _save_table\n    results = self._do_insert(\n  File \"/usr/local/lib/python3.10/site-packages/django/db/models/base.py\", line 1201, in _do_insert\n    return manager._insert(\n  File \"/usr/local/lib/python3.10/site-packages/django/db/models/manager.py\", line 87, in manager_method\n    return getattr(self.get_queryset(), name)(*args, **kwargs)\n  File \"/usr/local/lib/python3.10/site-packages/django/db/models/query.py\", line 1847, in _insert\n    return query.get_compiler(using=using).execute_sql(returning_fields)\n  File \"/usr/local/lib/python3.10/site-packages/django/db/models/sql/compiler.py\", line 1836, in execute_sql\n    cursor.execute(sql, params)\n  File \"/usr/local/lib/python3.10/site-packages/django/db/backends/utils.py\", line 122, in execute\n    return super().execute(sql, params)\n  File \"/usr/local/lib/python3.10/site-packages/django/db/backends/utils.py\", line 79, in execute\n    return self._execute_with_wrappers(\n  File \"/usr/local/lib/python3.10/site-packages/django/db/backends/utils.py\", line 92, in _execute_with_wrappers\n    return executor(sql, params, many, context)\n  File \"/usr/local/lib/python3.10/site-packages/django/db/backends/utils.py\", line 100, in _execute\n    with self.db.wrap_database_errors:\n  File \"/usr/local/lib/python3.10/site-packages/django/db/utils.py\", line 91, in __exit__\n    raise dj_exc_value.with_traceback(traceback) from exc_value\n  File \"/usr/local/lib/python3.10/site-packages/django/db/backends/utils.py\", line 105, in _execute\n    return self.cursor.execute(sql, params)\ndjango.db.utils.IntegrityError: duplicate key value violates unique constraint \"analytics_session_session_id_key\"\nDETAIL:  Key (session_id)=(session_f4c6ac02-136a-4e2e-9f2e-2171eb2810cb_1757255535) already exists.\n"}
{"timestamp": "2025-09-07T15:03:04.791538Z", "level": "ERROR", "logger": "django.request", "message": "Internal Server Error: /redis", "module": "log", "function": "log_response", "line": 248, "thread": 140474389608128, "process": 18, "status_code": 500, "environment": "development", "project": "fauxdan", "exception": "Traceback (most recent call last):\n  File \"/usr/local/lib/python3.10/site-packages/django/db/backends/utils.py\", line 105, in _execute\n    return self.cursor.execute(sql, params)\npsycopg2.errors.UniqueViolation: duplicate key value violates unique constraint \"analytics_session_session_id_key\"\nDETAIL:  Key (session_id)=(session_f4c6ac02-136a-4e2e-9f2e-2171eb2810cb_1757257384) already exists.\n\n\nThe above exception was the direct cause of the following exception:\n\nTraceback (most recent call last):\n  File \"/usr/local/lib/python3.10/site-packages/django/core/handlers/exception.py\", line 55, in inner\n    response = get_response(request)\n  File \"/usr/local/lib/python3.10/site-packages/django/utils/deprecation.py\", line 128, in __call__\n    response = self.process_request(request)\n  File \"/app/analytics/middleware.py\", line 84, in process_request\n    session = Session.objects.create(\n  File \"/usr/local/lib/python3.10/site-packages/django/db/models/manager.py\", line 87, in manager_method\n    return getattr(self.get_queryset(), name)(*args, **kwargs)\n  File \"/usr/local/lib/python3.10/site-packages/django/db/models/query.py\", line 679, in create\n    obj.save(force_insert=True, using=self.db)\n  File \"/usr/local/lib/python3.10/site-packages/django/db/models/base.py\", line 891, in save\n    self.save_base(\n  File \"/usr/local/lib/python3.10/site-packages/django/db/models/base.py\", line 997, in save_base\n    updated = self._save_table(\n  File \"/usr/local/lib/python3.10/site-packages/django/db/models/base.py\", line 1160, in _save_table\n    results = self._do_insert(\n  File \"/usr/local/lib/python3.10/site-packages/django/db/models/base.py\", line 1201, in _do_insert\n    return manager._insert(\n  File \"/usr/local/lib/python3.10/site-packages/django/db/models/manager.py\", line 87, in manager_method\n    return getattr(self.get_queryset(), name)(*args, **kwargs)\n  File \"/usr/local/lib/python3.10/site-packages/django/db/models/query.py\", line 1847, in _insert\n    return query.get_compiler(using=using).execute_sql(returning_fields)\n  File \"/usr/local/lib/python3.10/site-packages/django/db/models/sql/compiler.py\", line 1836, in execute_sql\n    cursor.execute(sql, params)\n  File \"/usr/local/lib/python3.10/site-packages/django/db/backends/utils.py\", line 122, in execute\n    return super().execute(sql, params)\n  File \"/usr/local/lib/python3.10/site-packages/django/db/backends/utils.py\", line 79, in execute\n    return self._execute_with_wrappers(\n  File \"/usr/local/lib/python3.10/site-packages/django/db/backends/utils.py\", line 92, in _execute_with_wrappers\n    return executor(sql, params, many, context)\n  File \"/usr/local/lib/python3.10/site-packages/django/db/backends/utils.py\", line 100, in _execute\n    with self.db.wrap_database_errors:\n  File \"/usr/local/lib/python3.10/site-packages/django/db/utils.py\", line 91, in __exit__\n    raise dj_exc_value.with_traceback(traceback) from exc_value\n  File \"/usr/local/lib/python3.10/site-packages/django/db/backends/utils.py\", line 105, in _execute\n    return self.cursor.execute(sql, params)\ndjango.db.utils.IntegrityError: duplicate key value violates unique constraint \"analytics_session_session_id_key\"\nDETAIL:  Key (session_id)=(session_f4c6ac02-136a-4e2e-9f2e-2171eb2810cb_1757257384) already exists.\n"}
{"timestamp": "2025-09-07T15:03:35.004066Z", "level": "ERROR", "logger": "django.request", "message": "Internal Server Error: /redis", "module": "log", "function": "log_response", "line": 248, "thread": 140474389608128, "process": 18, "status_code": 500, "environment": "development", "project": "fauxdan", "exception": "Traceback (most recent call last):\n  File \"/usr/local/lib/python3.10/site-packages/django/db/backends/utils.py\", line 105, in _execute\n    return self.cursor.execute(sql, params)\npsycopg2.errors.UniqueViolation: duplicate key value violates unique constraint \"analytics_session_session_id_key\"\nDETAIL:  Key (session_id)=(session_f4c6ac02-136a-4e2e-9f2e-2171eb2810cb_1757257414) already exists.\n\n\nThe above exception was the direct cause of the following exception:\n\nTraceback (most recent call last):\n  File \"/usr/local/lib/python3.10/site-packages/django/core/handlers/exception.py\", line 55, in inner\n    response = get_response(request)\n  File \"/usr/local/lib/python3.10/site-packages/django/utils/deprecation.py\", line 128, in __call__\n    response = self.process_request(request)\n  File \"/app/analytics/middleware.py\", line 84, in process_request\n    session = Session.objects.create(\n  File \"/usr/local/lib/python3.10/site-packages/django/db/models/manager.py\", line 87, in manager_method\n    return getattr(self.get_queryset(), name)(*args, **kwargs)\n  File \"/usr/local/lib/python3.10/site-packages/django/db/models/query.py\", line 679, in create\n    obj.save(force_insert=True, using=self.db)\n  File \"/usr/local/lib/python3.10/site-packages/django/db/models/base.py\", line 891, in save\n    self.save_base(\n  File \"/usr/local/lib/python3.10/site-packages/django/db/models/base.py\", line 997, in save_base\n    updated = self._save_table(\n  File \"/usr/local/lib/python3.10/site-packages/django/db/models/base.py\", line 1160, in _save_table\n    results = self._do_insert(\n  File \"/usr/local/lib/python3.10/site-packages/django/db/models/base.py\", line 1201, in _do_insert\n    return manager._insert(\n  File \"/usr/local/lib/python3.10/site-packages/django/db/models/manager.py\", line 87, in manager_method\n    return getattr(self.get_queryset(), name)(*args, **kwargs)\n  File \"/usr/local/lib/python3.10/site-packages/django/db/models/query.py\", line 1847, in _insert\n    return query.get_compiler(using=using).execute_sql(returning_fields)\n  File \"/usr/local/lib/python3.10/site-packages/django/db/models/sql/compiler.py\", line 1836, in execute_sql\n    cursor.execute(sql, params)\n  File \"/usr/local/lib/python3.10/site-packages/django/db/backends/utils.py\", line 122, in execute\n    return super().execute(sql, params)\n  File \"/usr/local/lib/python3.10/site-packages/django/db/backends/utils.py\", line 79, in execute\n    return self._execute_with_wrappers(\n  File \"/usr/local/lib/python3.10/site-packages/django/db/backends/utils.py\", line 92, in _execute_with_wrappers\n    return executor(sql, params, many, context)\n  File \"/usr/local/lib/python3.10/site-packages/django/db/backends/utils.py\", line 100, in _execute\n    with self.db.wrap_database_errors:\n  File \"/usr/local/lib/python3.10/site-packages/django/db/utils.py\", line 91, in __exit__\n    raise dj_exc_value.with_traceback(traceback) from exc_value\n  File \"/usr/local/lib/python3.10/site-packages/django/db/backends/utils.py\", line 105, in _execute\n    return self.cursor.execute(sql, params)\ndjango.db.utils.IntegrityError: duplicate key value violates unique constraint \"analytics_session_session_id_key\"\nDETAIL:  Key (session_id)=(session_f4c6ac02-136a-4e2e-9f2e-2171eb2810cb_1757257414) already exists.\n"}
{"timestamp": "2025-09-07T15:15:44.968383Z", "level": "ERROR", "logger": "django.request", "message": "Internal Server Error: /analytics/events/", "module": "log", "function": "log_response", "line": 248, "thread": 139720889710272, "process": 19, "status_code": 500, "environment": "development", "project": "fauxdan", "exception": "Traceback (most recent call last):\n  File \"/usr/local/lib/python3.10/site-packages/django/db/backends/utils.py\", line 105, in _execute\n    return self.cursor.execute(sql, params)\npsycopg2.errors.UniqueViolation: duplicate key value violates unique constraint \"analytics_session_session_id_key\"\nDETAIL:  Key (session_id)=(session_584441cb-db68-4405-b9ed-16156d75ce1c_1757258144) already exists.\n\n\nThe above exception was the direct cause of the following exception:\n\nTraceback (most recent call last):\n  File \"/usr/local/lib/python3.10/site-packages/django/core/handlers/exception.py\", line 55, in inner\n    response = get_response(request)\n  File \"/usr/local/lib/python3.10/site-packages/django/utils/deprecation.py\", line 128, in __call__\n    response = self.process_request(request)\n  File \"/app/analytics/middleware.py\", line 84, in process_request\n    session = Session.objects.create(\n  File \"/usr/local/lib/python3.10/site-packages/django/db/models/manager.py\", line 87, in manager_method\n    return getattr(self.get_queryset(), name)(*args, **kwargs)\n  File \"/usr/local/lib/python3.10/site-packages/django/db/models/query.py\", line 679, in create\n    obj.save(force_insert=True, using=self.db)\n  File \"/usr/local/lib/python3.10/site-packages/django/db/models/base.py\", line 891, in save\n    self.save_base(\n  File \"/usr/local/lib/python3.10/site-packages/django/db/models/base.py\", line 997, in save_base\n    updated = self._save_table(\n  File \"/usr/local/lib/python3.10/site-packages/django/db/models/base.py\", line 1160, in _save_table\n    results = self._do_insert(\n  File \"/usr/local/lib/python3.10/site-packages/django/db/models/base.py\", line 1201, in _do_insert\n    return manager._insert(\n  File \"/usr/local/lib/python3.10/site-packages/django/db/models/manager.py\", line 87, in manager_method\n    return getattr(self.get_queryset(), name)(*args, **kwargs)\n  File \"/usr/local/lib/python3.10/site-packages/django/db/models/query.py\", line 1847, in _insert\n    return query.get_compiler(using=using).execute_sql(returning_fields)\n  File \"/usr/local/lib/python3.10/site-packages/django/db/models/sql/compiler.py\", line 1836, in execute_sql\n    cursor.execute(sql, params)\n  File \"/usr/local/lib/python3.10/site-packages/django/db/backends/utils.py\", line 122, in execute\n    return super().execute(sql, params)\n  File \"/usr/local/lib/python3.10/site-packages/django/db/backends/utils.py\", line 79, in execute\n    return self._execute_with_wrappers(\n  File \"/usr/local/lib/python3.10/site-packages/django/db/backends/utils.py\", line 92, in _execute_with_wrappers\n    return executor(sql, params, many, context)\n  File \"/usr/local/lib/python3.10/site-packages/django/db/backends/utils.py\", line 100, in _execute\n    with self.db.wrap_database_errors:\n  File \"/usr/local/lib/python3.10/site-packages/django/db/utils.py\", line 91, in __exit__\n    raise dj_exc_value.with_traceback(traceback) from exc_value\n  File \"/usr/local/lib/python3.10/site-packages/django/db/backends/utils.py\", line 105, in _execute\n    return self.cursor.execute(sql, params)\ndjango.db.utils.IntegrityError: duplicate key value violates unique constraint \"analytics_session_session_id_key\"\nDETAIL:  Key (session_id)=(session_584441cb-db68-4405-b9ed-16156d75ce1c_1757258144) already exists.\n"}
{"timestamp": "2025-09-07T15:34:25.784530Z", "level": "ERROR", "logger": "django.request", "message": "Internal Server Error: /redis", "module": "log", "function": "log_response", "line": 248, "thread": 140474389608128, "process": 18, "status_code": 500, "environment": "development", "project": "fauxdan", "exception": "Traceback (most recent call last):\n  File \"/usr/local/lib/python3.10/site-packages/django/db/backends/utils.py\", line 105, in _execute\n    return self.cursor.execute(sql, params)\npsycopg2.errors.UniqueViolation: duplicate key value violates unique constraint \"analytics_session_session_id_key\"\nDETAIL:  Key (session_id)=(session_f4c6ac02-136a-4e2e-9f2e-2171eb2810cb_1757259265) already exists.\n\n\nThe above exception was the direct cause of the following exception:\n\nTraceback (most recent call last):\n  File \"/usr/local/lib/python3.10/site-packages/django/core/handlers/exception.py\", line 55, in inner\n    response = get_response(request)\n  File \"/usr/local/lib/python3.10/site-packages/django/utils/deprecation.py\", line 128, in __call__\n    response = self.process_request(request)\n  File \"/app/analytics/middleware.py\", line 84, in process_request\n    session = Session.objects.create(\n  File \"/usr/local/lib/python3.10/site-packages/django/db/models/manager.py\", line 87, in manager_method\n    return getattr(self.get_queryset(), name)(*args, **kwargs)\n  File \"/usr/local/lib/python3.10/site-packages/django/db/models/query.py\", line 679, in create\n    obj.save(force_insert=True, using=self.db)\n  File \"/usr/local/lib/python3.10/site-packages/django/db/models/base.py\", line 891, in save\n    self.save_base(\n  File \"/usr/local/lib/python3.10/site-packages/django/db/models/base.py\", line 997, in save_base\n    updated = self._save_table(\n  File \"/usr/local/lib/python3.10/site-packages/django/db/models/base.py\", line 1160, in _save_table\n    results = self._do_insert(\n  File \"/usr/local/lib/python3.10/site-packages/django/db/models/base.py\", line 1201, in _do_insert\n    return manager._insert(\n  File \"/usr/local/lib/python3.10/site-packages/django/db/models/manager.py\", line 87, in manager_method\n    return getattr(self.get_queryset(), name)(*args, **kwargs)\n  File \"/usr/local/lib/python3.10/site-packages/django/db/models/query.py\", line 1847, in _insert\n    return query.get_compiler(using=using).execute_sql(returning_fields)\n  File \"/usr/local/lib/python3.10/site-packages/django/db/models/sql/compiler.py\", line 1836, in execute_sql\n    cursor.execute(sql, params)\n  File \"/usr/local/lib/python3.10/site-packages/django/db/backends/utils.py\", line 122, in execute\n    return super().execute(sql, params)\n  File \"/usr/local/lib/python3.10/site-packages/django/db/backends/utils.py\", line 79, in execute\n    return self._execute_with_wrappers(\n  File \"/usr/local/lib/python3.10/site-packages/django/db/backends/utils.py\", line 92, in _execute_with_wrappers\n    return executor(sql, params, many, context)\n  File \"/usr/local/lib/python3.10/site-packages/django/db/backends/utils.py\", line 100, in _execute\n    with self.db.wrap_database_errors:\n  File \"/usr/local/lib/python3.10/site-packages/django/db/utils.py\", line 91, in __exit__\n    raise dj_exc_value.with_traceback(traceback) from exc_value\n  File \"/usr/local/lib/python3.10/site-packages/django/db/backends/utils.py\", line 105, in _execute\n    return self.cursor.execute(sql, params)\ndjango.db.utils.IntegrityError: duplicate key value violates unique constraint \"analytics_session_session_id_key\"\nDETAIL:  Key (session_id)=(session_f4c6ac02-136a-4e2e-9f2e-2171eb2810cb_1757259265) already exists.\n"}
{"timestamp": "2025-09-07T17:06:27.298067Z", "level": "ERROR", "logger": "django.request", "message": "Internal Server Error: /analytics/events/", "module": "log", "function": "log_response", "line": 248, "thread": 139751533819584, "process": 82, "status_code": 500, "environment": "development", "project": "fauxdan", "exception": "Traceback (most recent call last):\n  File \"/usr/local/lib/python3.10/site-packages/django/db/backends/utils.py\", line 105, in _execute\n    return self.cursor.execute(sql, params)\npsycopg2.errors.UniqueViolation: duplicate key value violates unique constraint \"analytics_session_session_id_key\"\nDETAIL:  Key (session_id)=(session_584441cb-db68-4405-b9ed-16156d75ce1c_1757264786) already exists.\n\n\nThe above exception was the direct cause of the following exception:\n\nTraceback (most recent call last):\n  File \"/usr/local/lib/python3.10/site-packages/django/core/handlers/exception.py\", line 55, in inner\n    response = get_response(request)\n  File \"/usr/local/lib/python3.10/site-packages/django/utils/deprecation.py\", line 128, in __call__\n    response = self.process_request(request)\n  File \"/app/analytics/middleware.py\", line 84, in process_request\n    session = Session.objects.create(\n  File \"/usr/local/lib/python3.10/site-packages/django/db/models/manager.py\", line 87, in manager_method\n    return getattr(self.get_queryset(), name)(*args, **kwargs)\n  File \"/usr/local/lib/python3.10/site-packages/django/db/models/query.py\", line 679, in create\n    obj.save(force_insert=True, using=self.db)\n  File \"/usr/local/lib/python3.10/site-packages/django/db/models/base.py\", line 891, in save\n    self.save_base(\n  File \"/usr/local/lib/python3.10/site-packages/django/db/models/base.py\", line 997, in save_base\n    updated = self._save_table(\n  File \"/usr/local/lib/python3.10/site-packages/django/db/models/base.py\", line 1160, in _save_table\n    results = self._do_insert(\n  File \"/usr/local/lib/python3.10/site-packages/django/db/models/base.py\", line 1201, in _do_insert\n    return manager._insert(\n  File \"/usr/local/lib/python3.10/site-packages/django/db/models/manager.py\", line 87, in manager_method\n    return getattr(self.get_queryset(), name)(*args, **kwargs)\n  File \"/usr/local/lib/python3.10/site-packages/django/db/models/query.py\", line 1847, in _insert\n    return query.get_compiler(using=using).execute_sql(returning_fields)\n  File \"/usr/local/lib/python3.10/site-packages/django/db/models/sql/compiler.py\", line 1836, in execute_sql\n    cursor.execute(sql, params)\n  File \"/usr/local/lib/python3.10/site-packages/django/db/backends/utils.py\", line 122, in execute\n    return super().execute(sql, params)\n  File \"/usr/local/lib/python3.10/site-packages/django/db/backends/utils.py\", line 79, in execute\n    return self._execute_with_wrappers(\n  File \"/usr/local/lib/python3.10/site-packages/django/db/backends/utils.py\", line 92, in _execute_with_wrappers\n    return executor(sql, params, many, context)\n  File \"/usr/local/lib/python3.10/site-packages/django/db/backends/utils.py\", line 100, in _execute\n    with self.db.wrap_database_errors:\n  File \"/usr/local/lib/python3.10/site-packages/django/db/utils.py\", line 91, in __exit__\n    raise dj_exc_value.with_traceback(traceback) from exc_value\n  File \"/usr/local/lib/python3.10/site-packages/django/db/backends/utils.py\", line 105, in _execute\n    return self.cursor.execute(sql, params)\ndjango.db.utils.IntegrityError: duplicate key value violates unique constraint \"analytics_session_session_id_key\"\nDETAIL:  Key (session_id)=(session_584441cb-db68-4405-b9ed-16156d75ce1c_1757264786) already exists.\n"}
{"timestamp": "2025-09-07T20:14:41.028598Z", "level": "ERROR", "logger": "django.request", "message": "Internal Server Error: /redis", "module": "log", "function": "log_response", "line": 248, "thread": 139743463466688, "process": 83, "status_code": 500, "environment": "development", "project": "fauxdan", "exception": "Traceback (most recent call last):\n  File \"/usr/local/lib/python3.10/site-packages/django/db/backends/utils.py\", line 105, in _execute\n    return self.cursor.execute(sql, params)\npsycopg2.errors.UniqueViolation: duplicate key value violates unique constraint \"analytics_session_session_id_key\"\nDETAIL:  Key (session_id)=(session_f4c6ac02-136a-4e2e-9f2e-2171eb2810cb_1757276080) already exists.\n\n\nThe above exception was the direct cause of the following exception:\n\nTraceback (most recent call last):\n  File \"/usr/local/lib/python3.10/site-packages/django/core/handlers/exception.py\", line 55, in inner\n    response = get_response(request)\n  File \"/usr/local/lib/python3.10/site-packages/django/utils/deprecation.py\", line 128, in __call__\n    response = self.process_request(request)\n  File \"/app/analytics/middleware.py\", line 84, in process_request\n    session = Session.objects.create(\n  File \"/usr/local/lib/python3.10/site-packages/django/db/models/manager.py\", line 87, in manager_method\n    return getattr(self.get_queryset(), name)(*args, **kwargs)\n  File \"/usr/local/lib/python3.10/site-packages/django/db/models/query.py\", line 679, in create\n    obj.save(force_insert=True, using=self.db)\n  File \"/usr/local/lib/python3.10/site-packages/django/db/models/base.py\", line 891, in save\n    self.save_base(\n  File \"/usr/local/lib/python3.10/site-packages/django/db/models/base.py\", line 997, in save_base\n    updated = self._save_table(\n  File \"/usr/local/lib/python3.10/site-packages/django/db/models/base.py\", line 1160, in _save_table\n    results = self._do_insert(\n  File \"/usr/local/lib/python3.10/site-packages/django/db/models/base.py\", line 1201, in _do_insert\n    return manager._insert(\n  File \"/usr/local/lib/python3.10/site-packages/django/db/models/manager.py\", line 87, in manager_method\n    return getattr(self.get_queryset(), name)(*args, **kwargs)\n  File \"/usr/local/lib/python3.10/site-packages/django/db/models/query.py\", line 1847, in _insert\n    return query.get_compiler(using=using).execute_sql(returning_fields)\n  File \"/usr/local/lib/python3.10/site-packages/django/db/models/sql/compiler.py\", line 1836, in execute_sql\n    cursor.execute(sql, params)\n  File \"/usr/local/lib/python3.10/site-packages/django/db/backends/utils.py\", line 122, in execute\n    return super().execute(sql, params)\n  File \"/usr/local/lib/python3.10/site-packages/django/db/backends/utils.py\", line 79, in execute\n    return self._execute_with_wrappers(\n  File \"/usr/local/lib/python3.10/site-packages/django/db/backends/utils.py\", line 92, in _execute_with_wrappers\n    return executor(sql, params, many, context)\n  File \"/usr/local/lib/python3.10/site-packages/django/db/backends/utils.py\", line 100, in _execute\n    with self.db.wrap_database_errors:\n  File \"/usr/local/lib/python3.10/site-packages/django/db/utils.py\", line 91, in __exit__\n    raise dj_exc_value.with_traceback(traceback) from exc_value\n  File \"/usr/local/lib/python3.10/site-packages/django/db/backends/utils.py\", line 105, in _execute\n    return self.cursor.execute(sql, params)\ndjango.db.utils.IntegrityError: duplicate key value violates unique constraint \"analytics_session_session_id_key\"\nDETAIL:  Key (session_id)=(session_f4c6ac02-136a-4e2e-9f2e-2171eb2810cb_1757276080) already exists.\n"}
{"timestamp": "2025-09-07T20:19:44.741083Z", "level": "ERROR", "logger": "django.request", "message": "Internal Server Error: /analytics/events/", "module": "log", "function": "log_response", "line": 248, "thread": 139751305762496, "process": 82, "status_code": 500, "environment": "development", "project": "fauxdan", "exception": "Traceback (most recent call last):\n  File \"/usr/local/lib/python3.10/site-packages/django/db/backends/utils.py\", line 105, in _execute\n    return self.cursor.execute(sql, params)\npsycopg2.errors.UniqueViolation: duplicate key value violates unique constraint \"analytics_session_session_id_key\"\nDETAIL:  Key (session_id)=(session_9a7c6eb8-48ce-480e-9c14-ca23fd40c646_1757276384) already exists.\n\n\nThe above exception was the direct cause of the following exception:\n\nTraceback (most recent call last):\n  File \"/usr/local/lib/python3.10/site-packages/django/core/handlers/exception.py\", line 55, in inner\n    response = get_response(request)\n  File \"/usr/local/lib/python3.10/site-packages/django/utils/deprecation.py\", line 128, in __call__\n    response = self.process_request(request)\n  File \"/app/analytics/middleware.py\", line 84, in process_request\n    session = Session.objects.create(\n  File \"/usr/local/lib/python3.10/site-packages/django/db/models/manager.py\", line 87, in manager_method\n    return getattr(self.get_queryset(), name)(*args, **kwargs)\n  File \"/usr/local/lib/python3.10/site-packages/django/db/models/query.py\", line 679, in create\n    obj.save(force_insert=True, using=self.db)\n  File \"/usr/local/lib/python3.10/site-packages/django/db/models/base.py\", line 891, in save\n    self.save_base(\n  File \"/usr/local/lib/python3.10/site-packages/django/db/models/base.py\", line 997, in save_base\n    updated = self._save_table(\n  File \"/usr/local/lib/python3.10/site-packages/django/db/models/base.py\", line 1160, in _save_table\n    results = self._do_insert(\n  File \"/usr/local/lib/python3.10/site-packages/django/db/models/base.py\", line 1201, in _do_insert\n    return manager._insert(\n  File \"/usr/local/lib/python3.10/site-packages/django/db/models/manager.py\", line 87, in manager_method\n    return getattr(self.get_queryset(), name)(*args, **kwargs)\n  File \"/usr/local/lib/python3.10/site-packages/django/db/models/query.py\", line 1847, in _insert\n    return query.get_compiler(using=using).execute_sql(returning_fields)\n  File \"/usr/local/lib/python3.10/site-packages/django/db/models/sql/compiler.py\", line 1836, in execute_sql\n    cursor.execute(sql, params)\n  File \"/usr/local/lib/python3.10/site-packages/django/db/backends/utils.py\", line 122, in execute\n    return super().execute(sql, params)\n  File \"/usr/local/lib/python3.10/site-packages/django/db/backends/utils.py\", line 79, in execute\n    return self._execute_with_wrappers(\n  File \"/usr/local/lib/python3.10/site-packages/django/db/backends/utils.py\", line 92, in _execute_with_wrappers\n    return executor(sql, params, many, context)\n  File \"/usr/local/lib/python3.10/site-packages/django/db/backends/utils.py\", line 100, in _execute\n    with self.db.wrap_database_errors:\n  File \"/usr/local/lib/python3.10/site-packages/django/db/utils.py\", line 91, in __exit__\n    raise dj_exc_value.with_traceback(traceback) from exc_value\n  File \"/usr/local/lib/python3.10/site-packages/django/db/backends/utils.py\", line 105, in _execute\n    return self.cursor.execute(sql, params)\ndjango.db.utils.IntegrityError: duplicate key value violates unique constraint \"analytics_session_session_id_key\"\nDETAIL:  Key (session_id)=(session_9a7c6eb8-48ce-480e-9c14-ca23fd40c646_1757276384) already exists.\n"}
{"timestamp": "2025-09-07T20:45:38.893367Z", "level": "ERROR", "logger": "django.request", "message": "Internal Server Error: /redis", "module": "log", "function": "log_response", "line": 248, "thread": 139743463466688, "process": 83, "status_code": 500, "environment": "development", "project": "fauxdan", "exception": "Traceback (most recent call last):\n  File \"/usr/local/lib/python3.10/site-packages/django/db/backends/utils.py\", line 105, in _execute\n    return self.cursor.execute(sql, params)\npsycopg2.errors.UniqueViolation: duplicate key value violates unique constraint \"analytics_session_session_id_key\"\nDETAIL:  Key (session_id)=(session_f4c6ac02-136a-4e2e-9f2e-2171eb2810cb_1757277938) already exists.\n\n\nThe above exception was the direct cause of the following exception:\n\nTraceback (most recent call last):\n  File \"/usr/local/lib/python3.10/site-packages/django/core/handlers/exception.py\", line 55, in inner\n    response = get_response(request)\n  File \"/usr/local/lib/python3.10/site-packages/django/utils/deprecation.py\", line 128, in __call__\n    response = self.process_request(request)\n  File \"/app/analytics/middleware.py\", line 84, in process_request\n    session = Session.objects.create(\n  File \"/usr/local/lib/python3.10/site-packages/django/db/models/manager.py\", line 87, in manager_method\n    return getattr(self.get_queryset(), name)(*args, **kwargs)\n  File \"/usr/local/lib/python3.10/site-packages/django/db/models/query.py\", line 679, in create\n    obj.save(force_insert=True, using=self.db)\n  File \"/usr/local/lib/python3.10/site-packages/django/db/models/base.py\", line 891, in save\n    self.save_base(\n  File \"/usr/local/lib/python3.10/site-packages/django/db/models/base.py\", line 997, in save_base\n    updated = self._save_table(\n  File \"/usr/local/lib/python3.10/site-packages/django/db/models/base.py\", line 1160, in _save_table\n    results = self._do_insert(\n  File \"/usr/local/lib/python3.10/site-packages/django/db/models/base.py\", line 1201, in _do_insert\n    return manager._insert(\n  File \"/usr/local/lib/python3.10/site-packages/django/db/models/manager.py\", line 87, in manager_method\n    return getattr(self.get_queryset(), name)(*args, **kwargs)\n  File \"/usr/local/lib/python3.10/site-packages/django/db/models/query.py\", line 1847, in _insert\n    return query.get_compiler(using=using).execute_sql(returning_fields)\n  File \"/usr/local/lib/python3.10/site-packages/django/db/models/sql/compiler.py\", line 1836, in execute_sql\n    cursor.execute(sql, params)\n  File \"/usr/local/lib/python3.10/site-packages/django/db/backends/utils.py\", line 122, in execute\n    return super().execute(sql, params)\n  File \"/usr/local/lib/python3.10/site-packages/django/db/backends/utils.py\", line 79, in execute\n    return self._execute_with_wrappers(\n  File \"/usr/local/lib/python3.10/site-packages/django/db/backends/utils.py\", line 92, in _execute_with_wrappers\n    return executor(sql, params, many, context)\n  File \"/usr/local/lib/python3.10/site-packages/django/db/backends/utils.py\", line 100, in _execute\n    with self.db.wrap_database_errors:\n  File \"/usr/local/lib/python3.10/site-packages/django/db/utils.py\", line 91, in __exit__\n    raise dj_exc_value.with_traceback(traceback) from exc_value\n  File \"/usr/local/lib/python3.10/site-packages/django/db/backends/utils.py\", line 105, in _execute\n    return self.cursor.execute(sql, params)\ndjango.db.utils.IntegrityError: duplicate key value violates unique constraint \"analytics_session_session_id_key\"\nDETAIL:  Key (session_id)=(session_f4c6ac02-136a-4e2e-9f2e-2171eb2810cb_1757277938) already exists.\n"}
{"timestamp": "2025-09-07T21:08:23.476558Z", "level": "ERROR", "logger": "django.request", "message": "Internal Server Error: /metrics/", "module": "log", "function": "log_response", "line": 248, "thread": 139751551653568, "process": 82, "status_code": 500, "environment": "development", "project": "fauxdan", "exception": "Traceback (most recent call last):\n  File \"/usr/local/lib/python3.10/site-packages/django/db/backends/base/base.py\", line 279, in ensure_connection\n    self.connect()\n  File \"/usr/local/lib/python3.10/site-packages/django/utils/asyncio.py\", line 26, in inner\n    return func(*args, **kwargs)\n  File \"/usr/local/lib/python3.10/site-packages/django/db/backends/base/base.py\", line 256, in connect\n    self.connection = self.get_new_connection(conn_params)\n  File \"/usr/local/lib/python3.10/site-packages/django/utils/asyncio.py\", line 26, in inner\n    return func(*args, **kwargs)\n  File \"/usr/local/lib/python3.10/site-packages/django/db/backends/postgresql/base.py\", line 332, in get_new_connection\n    connection = self.Database.connect(**conn_params)\n  File \"/usr/local/lib/python3.10/site-packages/psycopg2/__init__.py\", line 122, in connect\n    conn = _connect(dsn, connection_factory=connection_factory, **kwasync)\npsycopg2.OperationalError: connection to server at \"db\" (172.18.0.16), port 5432 failed: FATAL:  the database system is shutting down\n\n\nThe above exception was the direct cause of the following exception:\n\nTraceback (most recent call last):\n  File \"/usr/local/lib/python3.10/site-packages/django/core/handlers/exception.py\", line 55, in inner\n    response = get_response(request)\n  File \"/usr/local/lib/python3.10/site-packages/django/utils/deprecation.py\", line 128, in __call__\n    response = self.process_request(request)\n  File \"/app/analytics/middleware.py\", line 41, in process_request\n    visitor, created = Visitor.objects.get_or_create(\n  File \"/usr/local/lib/python3.10/site-packages/django/db/models/manager.py\", line 87, in manager_method\n    return getattr(self.get_queryset(), name)(*args, **kwargs)\n  File \"/usr/local/lib/python3.10/site-packages/django/db/models/query.py\", line 948, in get_or_create\n    return self.get(**kwargs), False\n  File \"/usr/local/lib/python3.10/site-packages/django/db/models/query.py\", line 645, in get\n    num = len(clone)\n  File \"/usr/local/lib/python3.10/site-packages/django/db/models/query.py\", line 382, in __len__\n    self._fetch_all()\n  File \"/usr/local/lib/python3.10/site-packages/django/db/models/query.py\", line 1928, in _fetch_all\n    self._result_cache = list(self._iterable_class(self))\n  File \"/usr/local/lib/python3.10/site-packages/django/db/models/query.py\", line 91, in __iter__\n    results = compiler.execute_sql(\n  File \"/usr/local/lib/python3.10/site-packages/django/db/models/sql/compiler.py\", line 1572, in execute_sql\n    cursor = self.connection.cursor()\n  File \"/usr/local/lib/python3.10/site-packages/django/utils/asyncio.py\", line 26, in inner\n    return func(*args, **kwargs)\n  File \"/usr/local/lib/python3.10/site-packages/django/db/backends/base/base.py\", line 320, in cursor\n    return self._cursor()\n  File \"/usr/local/lib/python3.10/site-packages/django/db/backends/base/base.py\", line 296, in _cursor\n    self.ensure_connection()\n  File \"/usr/local/lib/python3.10/site-packages/django/utils/asyncio.py\", line 26, in inner\n    return func(*args, **kwargs)\n  File \"/usr/local/lib/python3.10/site-packages/django/db/backends/base/base.py\", line 278, in ensure_connection\n    with self.wrap_database_errors:\n  File \"/usr/local/lib/python3.10/site-packages/django/db/utils.py\", line 91, in __exit__\n    raise dj_exc_value.with_traceback(traceback) from exc_value\n  File \"/usr/local/lib/python3.10/site-packages/django/db/backends/base/base.py\", line 279, in ensure_connection\n    self.connect()\n  File \"/usr/local/lib/python3.10/site-packages/django/utils/asyncio.py\", line 26, in inner\n    return func(*args, **kwargs)\n  File \"/usr/local/lib/python3.10/site-packages/django/db/backends/base/base.py\", line 256, in connect\n    self.connection = self.get_new_connection(conn_params)\n  File \"/usr/local/lib/python3.10/site-packages/django/utils/asyncio.py\", line 26, in inner\n    return func(*args, **kwargs)\n  File \"/usr/local/lib/python3.10/site-packages/django/db/backends/postgresql/base.py\", line 332, in get_new_connection\n    connection = self.Database.connect(**conn_params)\n  File \"/usr/local/lib/python3.10/site-packages/psycopg2/__init__.py\", line 122, in connect\n    conn = _connect(dsn, connection_factory=connection_factory, **kwasync)\ndjango.db.utils.OperationalError: connection to server at \"db\" (172.18.0.16), port 5432 failed: FATAL:  the database system is shutting down\n"}
